<?xml version="1.0" encoding="utf-8" ?>
code/simulation/urdf/myUr5/meshes
<!--            <mesh filename="/code/simulation/urdf/myUr5/meshes/base.stl"/>       -->
<!--            <mesh filename="/code/simulation/urdf/myUr5/meshes/forearm.stl"/>    -->
<!--            <mesh filename="/code/simulation/urdf/myUr5/meshes/shoulder.stl"/>   -->
<!--            <mesh filename="/code/simulation/urdf/myUr5/meshes/upperarm.stl"/>   -->
<!--            <mesh filename="/code/simulation/urdf/myUr5/meshes/wrist1.stl"/>     -->
<!--            <mesh filename="/code/simulation/urdf/myUr5/meshes/wrist2.stl"/>     -->
<!--            <mesh filename="/code/simulation/urdf/myUr5/meshes/wrist3.stl"/>     -->

<robot name="ur5">
    <material name="Lake_blue">
        <color rgba="0.8 1 1 1"/>
    </material>

    <material name="Light_grey">
        <color rgba="0.866 0.866 0.866 1"/>
    </material>

    <material name="Dark_grey">
        <color rgba="0.502 0.502 0.502 1"/>
    </material>

    <link name="base_link">
        <visual>
            <origin xyz="0 0 0" rpy="0 0 0"/>
            <geometry>
                <mesh filename="/code/simulation/urdf/myUr5/meshes/base.stl"/>
            </geometry>
            <material name="Light_grey"/>
        </visual>
    </link>

    <link name="shoulder_link">
        <visual>
            <origin xyz="0 0 0" rpy="0 0 0"/>
            <geometry>
                <mesh filename="/code/simulation/urdf/myUr5/meshes/shoulder.stl"/>
            </geometry>
            <material name="Dark_grey"/>
        </visual>
    </link>

    <joint name="joint0" type="revolute">
        <!-- 0.089159 -->
        <origin xyz="0 0 0.0862" rpy="0 0 0"></origin>
        <axis xyz="0 0 1"/>
        <parent link="base_link" />
        <child link="shoulder_link"/>
        <!-- -360 - 360 -->
        <limit effort="30" velocity="1.0" lower="-6.28" upper="6.28" />
    </joint>

    <link name="upperarm_link">
        <visual>
            <origin xyz="0 0 0" rpy="0 0 0"/>
            <geometry>
                <mesh filename="/code/simulation/urdf/myUr5/meshes/upperarm.stl"/>
            </geometry>
            <material name="Lake_blue"/>
        </visual>
    </link>

    <joint name="joint1" type="revolute">
        <!-- 0.089159 -->
        <origin xyz="0 0.136 0" rpy="0 0 0"></origin>
        <axis xyz="0 1 0"/>
        <parent link="shoulder_link" />
        <child link="upperarm_link"/>
        <!-- -360 - 360 -->
        <limit effort="30" velocity="1.0" lower="-6.28" upper="6.28" />
    </joint>

    <link name="forearm_link">
        <visual>
            <origin xyz="0 0 0" rpy="0 0 0"/>
            <geometry>
                <mesh filename="/code/simulation/urdf/myUr5/meshes/forearm.stl"/>
            </geometry>
            <material name="Lake_blue"/>
        </visual>
    </link>

    <joint name="joint2" type="revolute">
        <!-- 0.089159 -->
        <origin xyz="0 -0.12 0.425" rpy="0 0 0"></origin>
        <axis xyz="0 1 0"/>
        <parent link="upperarm_link" />
        <child link="forearm_link"/>
        <!-- -360 - 360 -->
        <limit effort="30" velocity="1.0" lower="-6.28" upper="6.28" />
    </joint>

    <link name="wrist1_link">
        <visual>
            <origin xyz="0 0 0" rpy="0 0 0"/>
            <geometry>
                <mesh filename="/code/simulation/urdf/myUr5/meshes/wrist1.stl"/>
            </geometry>
            <material name="Dark_grey"/>
        </visual>
    </link>

    <joint name="joint3" type="revolute">
        <!-- 0.089159 -->
        <origin xyz="0 0 0.3922" rpy="0 0 0"></origin>
        <axis xyz="0 1 0"/>
        <parent link="forearm_link" />
        <child link="wrist1_link"/>
        <!-- -360 - 360 -->
        <limit effort="30" velocity="1.0" lower="-6.28" upper="6.28" />
    </joint>

    <link name="wrist2_link">
        <visual>
            <origin xyz="0 0 0" rpy="0 0 0"/>
            <geometry>
                <mesh filename="/code/simulation/urdf/myUr5/meshes/wrist2.stl"/>
            </geometry>
            <material name="Dark_grey"/>
        </visual>
    </link>

    <joint name="joint4" type="revolute">
        <!-- 0.089159 -->
        <origin xyz="0 0.093 -0.0015" rpy="0 0 0"></origin>
        <axis xyz="0 0 1"/>
        <parent link="wrist1_link" />
        <child link="wrist2_link"/>
        <!-- -360 - 360 -->
        <limit effort="30" velocity="1.0" lower="-6.28" upper="6.28" />
    </joint>

    <link name="wrist3_link">
        <visual>
            <origin xyz="0 0 0" rpy="0 0 0"/>
            <geometry>
                <mesh filename="/code/simulation/urdf/myUr5/meshes/wrist3.stl"/>
            </geometry>
            <material name="Light_grey"/>
        </visual>
    </link>

    <joint name="joint5" type="revolute">
        <!-- 0.089159 -->
        <origin xyz="0 0 0.0948" rpy="0 0 0"></origin>
        <axis xyz="0 1 0"/>
        <parent link="wrist2_link" />
        <child link="wrist3_link"/>
        <!-- -360 - 360 -->
        <limit effort="30" velocity="1.0" lower="-6.28" upper="6.28" />
    </joint>

</robot>

